terminate called after throwing an instance of 'std::runtime_error'
  what():  function not found
